Exception on /api/v1/entities/trabajador/123456 [GET]
Traceback (most recent call last):
  File "/home/rosendo/Desarrollo/CVG/Dev/venv38/lib/python3.8/site-packages/flask/app.py", line 1950, in full_dispatch_request
    rv = self.dispatch_request()
  File "/home/rosendo/Desarrollo/CVG/Dev/venv38/lib/python3.8/site-packages/flask/app.py", line 1936, in dispatch_request
    return self.view_functions[rule.endpoint](**req.view_args)
  File "/home/rosendo/Desarrollo/CVG/Dev/venv38/lib/python3.8/site-packages/flask_restplus/api.py", line 325, in wrapper
    resp = resource(*args, **kwargs)
  File "/home/rosendo/Desarrollo/CVG/Dev/venv38/lib/python3.8/site-packages/flask/views.py", line 89, in view
    return self.dispatch_request(*args, **kwargs)
  File "/home/rosendo/Desarrollo/CVG/Dev/venv38/lib/python3.8/site-packages/flask_restplus/resource.py", line 44, in dispatch_request
    resp = meth(*args, **kwargs)
  File "/home/rosendo/Desarrollo/CVG/Dev/venv38/lib/python3.8/site-packages/flask_restplus/marshalling.py", line 243, in wrapper
    resp = f(*args, **kwargs)
  File "/home/rosendo/Desarrollo/CVG/Dev/sinergia-backend-base/app/v1/resources/entities.py", line 346, in get
    data = GetTrabajadorUseCase().execute(security_credentials,query_params)
  File "/home/rosendo/Desarrollo/CVG/Dev/sinergia-backend-base/app/v1/use_cases/entities.py", line 54, in execute
    return TrabajadorRepository(username=security_credentials['username']).getByCedula(query_params['cedula'])
  File "/home/rosendo/Desarrollo/CVG/Dev/sinergia-backend-base/app/v1/repository/entities.py", line 374, in getByCedula
    trabajador = Trabajador.query.filter(Trabajador.cedula == cedula).first()
  File "/home/rosendo/Desarrollo/CVG/Dev/venv38/lib/python3.8/site-packages/flask_sqlalchemy/__init__.py", line 550, in __get__
    mapper = orm.class_mapper(type)
  File "/home/rosendo/Desarrollo/CVG/Dev/venv38/lib/python3.8/site-packages/sqlalchemy/orm/base.py", line 451, in class_mapper
    mapper = _inspect_mapped_class(class_, configure=configure)
  File "/home/rosendo/Desarrollo/CVG/Dev/venv38/lib/python3.8/site-packages/sqlalchemy/orm/base.py", line 430, in _inspect_mapped_class
    mapper._configure_all()
  File "/home/rosendo/Desarrollo/CVG/Dev/venv38/lib/python3.8/site-packages/sqlalchemy/orm/mapper.py", line 1352, in _configure_all
    configure_mappers()
  File "/home/rosendo/Desarrollo/CVG/Dev/venv38/lib/python3.8/site-packages/sqlalchemy/orm/mapper.py", line 3299, in configure_mappers
    mapper._post_configure_properties()
  File "/home/rosendo/Desarrollo/CVG/Dev/venv38/lib/python3.8/site-packages/sqlalchemy/orm/mapper.py", line 1965, in _post_configure_properties
    prop.init()
  File "/home/rosendo/Desarrollo/CVG/Dev/venv38/lib/python3.8/site-packages/sqlalchemy/orm/interfaces.py", line 197, in init
    self.do_init()
  File "/home/rosendo/Desarrollo/CVG/Dev/venv38/lib/python3.8/site-packages/sqlalchemy/orm/relationships.py", line 2081, in do_init
    self._generate_backref()
  File "/home/rosendo/Desarrollo/CVG/Dev/venv38/lib/python3.8/site-packages/sqlalchemy/orm/relationships.py", line 2332, in _generate_backref
    raise sa_exc.ArgumentError(
sqlalchemy.exc.ArgumentError: Error creating backref 'trabajador' on relationship 'Trabajador.beneficiarios': property of that name exists on mapper 'mapped class Beneficiario->beneficiario'
Exception on /api/v1/entities/trabajador/123456 [GET]
Traceback (most recent call last):
  File "/home/rosendo/Desarrollo/CVG/Dev/venv38/lib/python3.8/site-packages/flask/app.py", line 1950, in full_dispatch_request
    rv = self.dispatch_request()
  File "/home/rosendo/Desarrollo/CVG/Dev/venv38/lib/python3.8/site-packages/flask/app.py", line 1936, in dispatch_request
    return self.view_functions[rule.endpoint](**req.view_args)
  File "/home/rosendo/Desarrollo/CVG/Dev/venv38/lib/python3.8/site-packages/flask_restplus/api.py", line 325, in wrapper
    resp = resource(*args, **kwargs)
  File "/home/rosendo/Desarrollo/CVG/Dev/venv38/lib/python3.8/site-packages/flask/views.py", line 89, in view
    return self.dispatch_request(*args, **kwargs)
  File "/home/rosendo/Desarrollo/CVG/Dev/venv38/lib/python3.8/site-packages/flask_restplus/resource.py", line 44, in dispatch_request
    resp = meth(*args, **kwargs)
  File "/home/rosendo/Desarrollo/CVG/Dev/venv38/lib/python3.8/site-packages/flask_restplus/marshalling.py", line 243, in wrapper
    resp = f(*args, **kwargs)
  File "/home/rosendo/Desarrollo/CVG/Dev/sinergia-backend-base/app/v1/resources/entities.py", line 346, in get
    data = GetTrabajadorUseCase().execute(security_credentials,query_params)
  File "/home/rosendo/Desarrollo/CVG/Dev/sinergia-backend-base/app/v1/use_cases/entities.py", line 54, in execute
    return TrabajadorRepository(username=security_credentials['username']).getByCedula(query_params['cedula'])
  File "/home/rosendo/Desarrollo/CVG/Dev/sinergia-backend-base/app/v1/repository/entities.py", line 374, in getByCedula
    trabajador = Trabajador.query.filter(Trabajador.cedula == cedula).first()
  File "/home/rosendo/Desarrollo/CVG/Dev/venv38/lib/python3.8/site-packages/flask_sqlalchemy/__init__.py", line 550, in __get__
    mapper = orm.class_mapper(type)
  File "/home/rosendo/Desarrollo/CVG/Dev/venv38/lib/python3.8/site-packages/sqlalchemy/orm/base.py", line 451, in class_mapper
    mapper = _inspect_mapped_class(class_, configure=configure)
  File "/home/rosendo/Desarrollo/CVG/Dev/venv38/lib/python3.8/site-packages/sqlalchemy/orm/base.py", line 430, in _inspect_mapped_class
    mapper._configure_all()
  File "/home/rosendo/Desarrollo/CVG/Dev/venv38/lib/python3.8/site-packages/sqlalchemy/orm/mapper.py", line 1352, in _configure_all
    configure_mappers()
  File "/home/rosendo/Desarrollo/CVG/Dev/venv38/lib/python3.8/site-packages/sqlalchemy/orm/mapper.py", line 3299, in configure_mappers
    mapper._post_configure_properties()
  File "/home/rosendo/Desarrollo/CVG/Dev/venv38/lib/python3.8/site-packages/sqlalchemy/orm/mapper.py", line 1965, in _post_configure_properties
    prop.init()
  File "/home/rosendo/Desarrollo/CVG/Dev/venv38/lib/python3.8/site-packages/sqlalchemy/orm/interfaces.py", line 197, in init
    self.do_init()
  File "/home/rosendo/Desarrollo/CVG/Dev/venv38/lib/python3.8/site-packages/sqlalchemy/orm/relationships.py", line 2081, in do_init
    self._generate_backref()
  File "/home/rosendo/Desarrollo/CVG/Dev/venv38/lib/python3.8/site-packages/sqlalchemy/orm/relationships.py", line 2332, in _generate_backref
    raise sa_exc.ArgumentError(
sqlalchemy.exc.ArgumentError: Error creating backref 'trabajador' on relationship 'Trabajador.beneficiarios': property of that name exists on mapper 'mapped class Beneficiario->beneficiario'
